./Notebooks/xeno/06_cnmf/02_run_cnmf/sbatch_cnmf_script.sh
/sci/labs/yotamd/lab_share/avishai.wizel/python_envs/miniconda/envs/cnmf_1.7/lib/python3.10/site-packages/scanpy/preprocessing/_scale.py:309: UserWarning: Received a view of an AnnData. Making a copy.
  view_to_actual(adata)
/sci/labs/yotamd/lab_share/avishai.wizel/python_envs/miniconda/envs/cnmf_1.7/lib/python3.10/site-packages/scanpy/preprocessing/_scale.py:309: UserWarning: Received a view of an AnnData. Making a copy.
  view_to_actual(adata)
/sci/labs/yotamd/lab_share/avishai.wizel/python_envs/miniconda/envs/cnmf_1.7/lib/python3.10/site-packages/scanpy/preprocessing/_pca/__init__.py:227: FutureWarning: Argument `use_highly_variable` is deprecated, consider using the mask argument. Use_highly_variable=True can be called through mask_var="highly_variable". Use_highly_variable=False can be called through mask_var=None
  mask_var_param, mask_var = _handle_mask_var(adata, mask_var, use_highly_variable)
2025-12-23 14:24:26,736 - harmonypy - INFO - Computing initial centroids with sklearn.KMeans...
2025-12-23 14:24:33,196 - harmonypy - INFO - sklearn.KMeans initialization complete.
2025-12-23 14:24:33,446 - harmonypy - INFO - Iteration 1 of 20
2025-12-23 14:24:39,422 - harmonypy - INFO - Iteration 2 of 20
2025-12-23 14:24:44,478 - harmonypy - INFO - Iteration 3 of 20
2025-12-23 14:24:49,516 - harmonypy - INFO - Iteration 4 of 20
2025-12-23 14:24:54,655 - harmonypy - INFO - Iteration 5 of 20
2025-12-23 14:25:02,979 - harmonypy - INFO - Iteration 6 of 20
2025-12-23 14:25:07,906 - harmonypy - INFO - Converged after 6 iterations
WARNING: Your filename has more than two extensions: ['.Corrected', '.HVG', '.Varnorm', '.h5ad'].
Only considering the two last: ['.Varnorm', '.h5ad'].
WARNING: Your filename has more than two extensions: ['.Corrected', '.HVG', '.Varnorm', '.h5ad'].
Only considering the two last: ['.Varnorm', '.h5ad'].
WARNING: Your filename has more than two extensions: ['.Corrected', '.HVG', '.Varnorm', '.h5ad'].
Only considering the two last: ['.Varnorm', '.h5ad'].
WARNING: Your filename has more than two extensions: ['.Corrected', '.HVG', '.Varnorm', '.h5ad'].
Only considering the two last: ['.Varnorm', '.h5ad'].
./Reports/xeno/06_cnmf/02_run_cnmf_1.7/xeno_batchCorrect/
harmony...
cnmf prepering...
factorizing...
[Worker 2]. Starting task 2.
[Worker 2]. Starting task 6.
[Worker 2]. Starting task 10.
[Worker 2]. Starting task 14.
[Worker 2]. Starting task 18.
[Worker 2]. Starting task 22.
[Worker 2]. Starting task 26.
[Worker 2]. Starting task 30.
[Worker 2]. Starting task 34.
[Worker 2]. Starting task 38.
[Worker 2]. Starting task 42.
[Worker 2]. Starting task 46.
[Worker 2]. Starting task 50.
[Worker 2]. Starting task 54.
[Worker 2]. Starting task 58.
[Worker 2]. Starting task 62.
[Worker 2]. Starting task 66.
[Worker 2]. Starting task 70.
[Worker 2]. Starting task 74.
[Worker 2]. Starting task 78.
[Worker 2]. Starting task 82.
[Worker 2]. Starting task 86.
[Worker 2]. Starting task 90.
[Worker 2]. Starting task 94.
[Worker 2]. Starting task 98.
[Worker 2]. Starting task 102.
[Worker 2]. Starting task 106.
[Worker 2]. Starting task 110.
[Worker 2]. Starting task 114.
[Worker 2]. Starting task 118.
[Worker 2]. Starting task 122.
[Worker 2]. Starting task 126.
[Worker 2]. Starting task 130.
[Worker 2]. Starting task 134.
[Worker 2]. Starting task 138.
[Worker 2]. Starting task 142.
[Worker 2]. Starting task 146.
[Worker 2]. Starting task 150.
[Worker 2]. Starting task 154.
[Worker 2]. Starting task 158.
[Worker 2]. Starting task 162.
[Worker 2]. Starting task 166.
[Worker 2]. Starting task 170.
[Worker 2]. Starting task 174.
[Worker 2]. Starting task 178.
[Worker 2]. Starting task 182.
[Worker 2]. Starting task 186.
[Worker 2]. Starting task 190.
[Worker 2]. Starting task 194.
[Worker 2]. Starting task 198.
[Worker 2]. Starting task 202.
[Worker 2]. Starting task 206.
[Worker 2]. Starting task 210.
[Worker 2]. Starting task 214.
[Worker 2]. Starting task 218.
[Worker 2]. Starting task 222.
[Worker 2]. Starting task 226.
[Worker 2]. Starting task 230.
[Worker 2]. Starting task 234.
[Worker 2]. Starting task 238.
[Worker 2]. Starting task 242.
[Worker 2]. Starting task 246.
[Worker 2]. Starting task 250.
[Worker 2]. Starting task 254.
[Worker 2]. Starting task 258.
[Worker 2]. Starting task 262.
[Worker 2]. Starting task 266.
[Worker 2]. Starting task 270.
[Worker 2]. Starting task 274.
[Worker 2]. Starting task 278.
[Worker 2]. Starting task 282.
[Worker 2]. Starting task 286.
[Worker 2]. Starting task 290.
[Worker 2]. Starting task 294.
[Worker 2]. Starting task 298.
[Worker 2]. Starting task 302.
[Worker 2]. Starting task 306.
[Worker 2]. Starting task 310.
[Worker 2]. Starting task 314.
[Worker 2]. Starting task 318.
[Worker 2]. Starting task 322.
[Worker 2]. Starting task 326.
[Worker 2]. Starting task 330.
[Worker 2]. Starting task 334.
[Worker 2]. Starting task 338.
[Worker 2]. Starting task 342.
[Worker 2]. Starting task 346.
[Worker 2]. Starting task 350.
[Worker 2]. Starting task 354.
[Worker 2]. Starting task 358.
[Worker 2]. Starting task 362.
[Worker 2]. Starting task 366.
[Worker 2]. Starting task 370.
[Worker 2]. Starting task 374.
[Worker 2]. Starting task 378.
[Worker 2]. Starting task 382.
[Worker 2]. Starting task 386.
[Worker 2]. Starting task 390.
[Worker 2]. Starting task 394.
[Worker 2]. Starting task 398.
[Worker 2]. Starting task 402.
[Worker 2]. Starting task 406.
[Worker 2]. Starting task 410.
[Worker 2]. Starting task 414.
[Worker 2]. Starting task 418.
[Worker 2]. Starting task 422.
[Worker 2]. Starting task 426.
[Worker 2]. Starting task 430.
[Worker 2]. Starting task 434.
[Worker 2]. Starting task 438.
[Worker 2]. Starting task 442.
[Worker 2]. Starting task 446.
[Worker 2]. Starting task 450.
[Worker 2]. Starting task 454.
[Worker 2]. Starting task 458.
[Worker 2]. Starting task 462.
[Worker 2]. Starting task 466.
[Worker 2]. Starting task 470.
[Worker 2]. Starting task 474.
[Worker 2]. Starting task 478.
[Worker 2]. Starting task 482.
[Worker 2]. Starting task 486.
[Worker 2]. Starting task 490.
[Worker 2]. Starting task 494.
[Worker 2]. Starting task 498.
[Worker 2]. Starting task 502.
[Worker 2]. Starting task 506.
[Worker 2]. Starting task 510.
[Worker 2]. Starting task 514.
[Worker 2]. Starting task 518.
[Worker 2]. Starting task 522.
[Worker 2]. Starting task 526.
[Worker 2]. Starting task 530.
[Worker 2]. Starting task 534.
[Worker 2]. Starting task 538.
[Worker 2]. Starting task 542.
[Worker 2]. Starting task 546.
[Worker 2]. Starting task 550.
[Worker 2]. Starting task 554.
[Worker 2]. Starting task 558.
[Worker 2]. Starting task 562.
[Worker 2]. Starting task 566.
[Worker 2]. Starting task 570.
[Worker 2]. Starting task 574.
[Worker 2]. Starting task 578.
[Worker 2]. Starting task 582.
[Worker 2]. Starting task 586.
[Worker 2]. Starting task 590.
[Worker 2]. Starting task 594.
[Worker 2]. Starting task 598.
[Worker 2]. Starting task 602.
[Worker 2]. Starting task 606.
[Worker 2]. Starting task 610.
[Worker 2]. Starting task 614.
[Worker 2]. Starting task 618.
[Worker 2]. Starting task 622.
[Worker 2]. Starting task 626.
[Worker 2]. Starting task 630.
[Worker 2]. Starting task 634.
[Worker 2]. Starting task 638.
[Worker 2]. Starting task 642.
[Worker 2]. Starting task 646.
[Worker 2]. Starting task 650.
[Worker 2]. Starting task 654.
[Worker 2]. Starting task 658.
[Worker 2]. Starting task 662.
[Worker 2]. Starting task 666.
[Worker 2]. Starting task 670.
[Worker 2]. Starting task 674.
[Worker 2]. Starting task 678.
[Worker 2]. Starting task 682.
[Worker 2]. Starting task 686.
[Worker 2]. Starting task 690.
[Worker 2]. Starting task 694.
[Worker 2]. Starting task 698.
[Worker 2]. Starting task 702.
[Worker 2]. Starting task 706.
[Worker 2]. Starting task 710.
[Worker 2]. Starting task 714.
[Worker 2]. Starting task 718.
[Worker 2]. Starting task 722.
[Worker 2]. Starting task 726.
[Worker 2]. Starting task 730.
[Worker 2]. Starting task 734.
[Worker 2]. Starting task 738.
[Worker 2]. Starting task 742.
[Worker 2]. Starting task 746.
[Worker 2]. Starting task 750.
[Worker 2]. Starting task 754.
[Worker 2]. Starting task 758.
[Worker 2]. Starting task 762.
[Worker 2]. Starting task 766.
[Worker 2]. Starting task 770.
[Worker 2]. Starting task 774.
[Worker 2]. Starting task 778.
[Worker 2]. Starting task 782.
[Worker 2]. Starting task 786.
[Worker 2]. Starting task 790.
[Worker 2]. Starting task 794.
[Worker 2]. Starting task 798.
[Worker 0]. Starting task 0.
[Worker 0]. Starting task 4.
[Worker 0]. Starting task 8.
[Worker 0]. Starting task 12.
[Worker 0]. Starting task 16.
[Worker 0]. Starting task 20.
[Worker 0]. Starting task 24.
[Worker 0]. Starting task 28.
[Worker 0]. Starting task 32.
[Worker 0]. Starting task 36.
[Worker 0]. Starting task 40.
[Worker 0]. Starting task 44.
[Worker 0]. Starting task 48.
[Worker 0]. Starting task 52.
[Worker 0]. Starting task 56.
[Worker 0]. Starting task 60.
[Worker 0]. Starting task 64.
[Worker 0]. Starting task 68.
[Worker 0]. Starting task 72.
[Worker 0]. Starting task 76.
[Worker 0]. Starting task 80.
[Worker 0]. Starting task 84.
[Worker 0]. Starting task 88.
[Worker 0]. Starting task 92.
[Worker 0]. Starting task 96.
[Worker 0]. Starting task 100.
[Worker 0]. Starting task 104.
[Worker 0]. Starting task 108.
[Worker 0]. Starting task 112.
[Worker 0]. Starting task 116.
[Worker 0]. Starting task 120.
[Worker 0]. Starting task 124.
[Worker 0]. Starting task 128.
[Worker 0]. Starting task 132.
[Worker 0]. Starting task 136.
[Worker 0]. Starting task 140.
[Worker 0]. Starting task 144.
[Worker 0]. Starting task 148.
[Worker 0]. Starting task 152.
[Worker 0]. Starting task 156.
[Worker 0]. Starting task 160.
[Worker 0]. Starting task 164.
[Worker 0]. Starting task 168.
[Worker 0]. Starting task 172.
[Worker 0]. Starting task 176.
[Worker 0]. Starting task 180.
[Worker 0]. Starting task 184.
[Worker 0]. Starting task 188.
[Worker 0]. Starting task 192.
[Worker 0]. Starting task 196.
[Worker 0]. Starting task 200.
[Worker 0]. Starting task 204.
[Worker 0]. Starting task 208.
[Worker 0]. Starting task 212.
[Worker 0]. Starting task 216.
[Worker 0]. Starting task 220.
[Worker 0]. Starting task 224.
[Worker 0]. Starting task 228.
[Worker 0]. Starting task 232.
[Worker 0]. Starting task 236.
[Worker 0]. Starting task 240.
[Worker 0]. Starting task 244.
[Worker 0]. Starting task 248.
[Worker 0]. Starting task 252.
[Worker 0]. Starting task 256.
[Worker 0]. Starting task 260.
[Worker 0]. Starting task 264.
[Worker 0]. Starting task 268.
[Worker 0]. Starting task 272.
[Worker 0]. Starting task 276.
[Worker 0]. Starting task 280.
[Worker 0]. Starting task 284.
[Worker 0]. Starting task 288.
[Worker 0]. Starting task 292.
[Worker 0]. Starting task 296.
[Worker 0]. Starting task 300.
[Worker 0]. Starting task 304.
[Worker 0]. Starting task 308.
[Worker 0]. Starting task 312.
[Worker 0]. Starting task 316.
[Worker 0]. Starting task 320.
[Worker 0]. Starting task 324.
[Worker 0]. Starting task 328.
[Worker 0]. Starting task 332.
[Worker 0]. Starting task 336.
[Worker 0]. Starting task 340.
[Worker 0]. Starting task 344.
[Worker 0]. Starting task 348.
[Worker 0]. Starting task 352.
[Worker 0]. Starting task 356.
[Worker 0]. Starting task 360.
[Worker 0]. Starting task 364.
[Worker 0]. Starting task 368.
[Worker 0]. Starting task 372.
[Worker 0]. Starting task 376.
[Worker 0]. Starting task 380.
[Worker 0]. Starting task 384.
[Worker 0]. Starting task 388.
[Worker 0]. Starting task 392.
[Worker 0]. Starting task 396.
[Worker 0]. Starting task 400.
[Worker 0]. Starting task 404.
[Worker 0]. Starting task 408.
[Worker 0]. Starting task 412.
[Worker 0]. Starting task 416.
[Worker 0]. Starting task 420.
[Worker 0]. Starting task 424.
[Worker 0]. Starting task 428.
[Worker 0]. Starting task 432.
[Worker 0]. Starting task 436.
[Worker 0]. Starting task 440.
[Worker 0]. Starting task 444.
[Worker 0]. Starting task 448.
[Worker 0]. Starting task 452.
[Worker 0]. Starting task 456.
[Worker 0]. Starting task 460.
[Worker 0]. Starting task 464.
[Worker 0]. Starting task 468.
[Worker 0]. Starting task 472.
[Worker 0]. Starting task 476.
[Worker 0]. Starting task 480.
[Worker 0]. Starting task 484.
[Worker 0]. Starting task 488.
[Worker 0]. Starting task 492.
[Worker 0]. Starting task 496.
[Worker 0]. Starting task 500.
[Worker 0]. Starting task 504.
[Worker 0]. Starting task 508.
[Worker 0]. Starting task 512.
[Worker 0]. Starting task 516.
[Worker 0]. Starting task 520.
[Worker 0]. Starting task 524.
[Worker 0]. Starting task 528.
[Worker 0]. Starting task 532.
[Worker 0]. Starting task 536.
[Worker 0]. Starting task 540.
[Worker 0]. Starting task 544.
[Worker 0]. Starting task 548.
[Worker 0]. Starting task 552.
[Worker 0]. Starting task 556.
[Worker 0]. Starting task 560.
[Worker 0]. Starting task 564.
[Worker 0]. Starting task 568.
[Worker 0]. Starting task 572.
[Worker 0]. Starting task 576.
[Worker 0]. Starting task 580.
[Worker 0]. Starting task 584.
[Worker 0]. Starting task 588.
[Worker 0]. Starting task 592.
[Worker 0]. Starting task 596.
[Worker 0]. Starting task 600.
[Worker 0]. Starting task 604.
[Worker 0]. Starting task 608.
[Worker 0]. Starting task 612.
[Worker 0]. Starting task 616.
[Worker 0]. Starting task 620.
[Worker 0]. Starting task 624.
[Worker 0]. Starting task 628.
[Worker 0]. Starting task 632.
[Worker 0]. Starting task 636.
[Worker 0]. Starting task 640.
[Worker 0]. Starting task 644.
[Worker 0]. Starting task 648.
[Worker 0]. Starting task 652.
[Worker 0]. Starting task 656.
[Worker 0]. Starting task 660.
[Worker 0]. Starting task 664.
[Worker 0]. Starting task 668.
[Worker 0]. Starting task 672.
[Worker 0]. Starting task 676.
[Worker 0]. Starting task 680.
[Worker 0]. Starting task 684.
[Worker 0]. Starting task 688.
[Worker 0]. Starting task 692.
[Worker 0]. Starting task 696.
[Worker 0]. Starting task 700.
[Worker 0]. Starting task 704.
[Worker 0]. Starting task 708.
[Worker 0]. Starting task 712.
[Worker 0]. Starting task 716.
[Worker 0]. Starting task 720.
[Worker 0]. Starting task 724.
[Worker 0]. Starting task 728.
[Worker 0]. Starting task 732.
[Worker 0]. Starting task 736.
[Worker 0]. Starting task 740.
[Worker 0]. Starting task 744.
[Worker 0]. Starting task 748.
[Worker 0]. Starting task 752.
[Worker 0]. Starting task 756.
[Worker 0]. Starting task 760.
[Worker 0]. Starting task 764.
[Worker 0]. Starting task 768.
[Worker 0]. Starting task 772.
[Worker 0]. Starting task 776.
[Worker 0]. Starting task 780.
[Worker 0]. Starting task 784.
[Worker 0]. Starting task 788.
[Worker 0]. Starting task 792.
[Worker 0]. Starting task 796.
[Worker 1]. Starting task 1.
[Worker 1]. Starting task 5.
[Worker 1]. Starting task 9.
[Worker 1]. Starting task 13.
[Worker 1]. Starting task 17.
[Worker 1]. Starting task 21.
[Worker 1]. Starting task 25.
[Worker 1]. Starting task 29.
[Worker 1]. Starting task 33.
[Worker 1]. Starting task 37.
[Worker 1]. Starting task 41.
[Worker 1]. Starting task 45.
[Worker 1]. Starting task 49.
[Worker 1]. Starting task 53.
[Worker 1]. Starting task 57.
[Worker 1]. Starting task 61.
[Worker 1]. Starting task 65.
[Worker 1]. Starting task 69.
[Worker 1]. Starting task 73.
[Worker 1]. Starting task 77.
[Worker 1]. Starting task 81.
[Worker 1]. Starting task 85.
[Worker 1]. Starting task 89.
[Worker 1]. Starting task 93.
[Worker 1]. Starting task 97.
[Worker 1]. Starting task 101.
[Worker 1]. Starting task 105.
[Worker 1]. Starting task 109.
[Worker 1]. Starting task 113.
[Worker 1]. Starting task 117.
[Worker 1]. Starting task 121.
[Worker 1]. Starting task 125.
[Worker 1]. Starting task 129.
[Worker 1]. Starting task 133.
[Worker 1]. Starting task 137.
[Worker 1]. Starting task 141.
[Worker 1]. Starting task 145.
[Worker 1]. Starting task 149.
[Worker 1]. Starting task 153.
[Worker 1]. Starting task 157.
[Worker 1]. Starting task 161.
[Worker 1]. Starting task 165.
[Worker 1]. Starting task 169.
[Worker 1]. Starting task 173.
[Worker 1]. Starting task 177.
[Worker 1]. Starting task 181.
[Worker 1]. Starting task 185.
[Worker 1]. Starting task 189.
[Worker 1]. Starting task 193.
[Worker 1]. Starting task 197.
[Worker 1]. Starting task 201.
[Worker 1]. Starting task 205.
[Worker 1]. Starting task 209.
[Worker 1]. Starting task 213.
[Worker 1]. Starting task 217.
[Worker 1]. Starting task 221.
[Worker 1]. Starting task 225.
[Worker 1]. Starting task 229.
[Worker 1]. Starting task 233.
[Worker 1]. Starting task 237.
[Worker 1]. Starting task 241.
[Worker 1]. Starting task 245.
[Worker 1]. Starting task 249.
[Worker 1]. Starting task 253.
[Worker 1]. Starting task 257.
[Worker 1]. Starting task 261.
[Worker 1]. Starting task 265.
[Worker 1]. Starting task 269.
[Worker 1]. Starting task 273.
[Worker 1]. Starting task 277.
[Worker 1]. Starting task 281.
[Worker 1]. Starting task 285.
[Worker 1]. Starting task 289.
[Worker 1]. Starting task 293.
[Worker 1]. Starting task 297.
[Worker 1]. Starting task 301.
[Worker 1]. Starting task 305.
[Worker 1]. Starting task 309.
[Worker 1]. Starting task 313.
[Worker 1]. Starting task 317.
[Worker 1]. Starting task 321.
[Worker 1]. Starting task 325.
[Worker 1]. Starting task 329.
[Worker 1]. Starting task 333.
[Worker 1]. Starting task 337.
[Worker 1]. Starting task 341.
[Worker 1]. Starting task 345.
[Worker 1]. Starting task 349.
[Worker 1]. Starting task 353.
[Worker 1]. Starting task 357.
[Worker 1]. Starting task 361.
[Worker 1]. Starting task 365.
[Worker 1]. Starting task 369.
[Worker 1]. Starting task 373.
[Worker 1]. Starting task 377.
[Worker 1]. Starting task 381.
[Worker 1]. Starting task 385.
[Worker 1]. Starting task 389.
[Worker 1]. Starting task 393.
[Worker 1]. Starting task 397.
[Worker 1]. Starting task 401.
[Worker 1]. Starting task 405.
[Worker 1]. Starting task 409.
[Worker 1]. Starting task 413.
[Worker 1]. Starting task 417.
[Worker 1]. Starting task 421.
[Worker 1]. Starting task 425.
[Worker 1]. Starting task 429.
[Worker 1]. Starting task 433.
[Worker 1]. Starting task 437.
[Worker 1]. Starting task 441.
[Worker 1]. Starting task 445.
[Worker 1]. Starting task 449.
[Worker 1]. Starting task 453.
[Worker 1]. Starting task 457.
[Worker 1]. Starting task 461.
[Worker 1]. Starting task 465.
[Worker 1]. Starting task 469.
[Worker 1]. Starting task 473.
[Worker 1]. Starting task 477.
[Worker 1]. Starting task 481.
[Worker 1]. Starting task 485.
[Worker 1]. Starting task 489.
[Worker 1]. Starting task 493.
[Worker 1]. Starting task 497.
[Worker 1]. Starting task 501.
[Worker 1]. Starting task 505.
[Worker 1]. Starting task 509.
[Worker 1]. Starting task 513.
[Worker 1]. Starting task 517.
[Worker 1]. Starting task 521.
[Worker 1]. Starting task 525.
[Worker 1]. Starting task 529.
[Worker 1]. Starting task 533.
[Worker 1]. Starting task 537.
[Worker 1]. Starting task 541.
[Worker 1]. Starting task 545.
[Worker 1]. Starting task 549.
[Worker 1]. Starting task 553.
[Worker 1]. Starting task 557.
[Worker 1]. Starting task 561.
[Worker 1]. Starting task 565.
[Worker 1]. Starting task 569.
[Worker 1]. Starting task 573.
[Worker 1]. Starting task 577.
[Worker 1]. Starting task 581.
[Worker 1]. Starting task 585.
[Worker 1]. Starting task 589.
[Worker 1]. Starting task 593.
[Worker 1]. Starting task 597.
[Worker 1]. Starting task 601.
[Worker 1]. Starting task 605.
[Worker 1]. Starting task 609.
[Worker 1]. Starting task 613.
[Worker 1]. Starting task 617.
[Worker 1]. Starting task 621.
[Worker 1]. Starting task 625.
[Worker 1]. Starting task 629.
[Worker 1]. Starting task 633.
[Worker 1]. Starting task 637.
[Worker 1]. Starting task 641.
[Worker 1]. Starting task 645.
[Worker 1]. Starting task 649.
[Worker 1]. Starting task 653.
[Worker 1]. Starting task 657.
[Worker 1]. Starting task 661.
[Worker 1]. Starting task 665.
[Worker 1]. Starting task 669.
[Worker 1]. Starting task 673.
[Worker 1]. Starting task 677.
[Worker 1]. Starting task 681.
[Worker 1]. Starting task 685.
[Worker 1]. Starting task 689.
[Worker 1]. Starting task 693.
[Worker 1]. Starting task 697.
[Worker 1]. Starting task 701.
[Worker 1]. Starting task 705.
[Worker 1]. Starting task 709.
[Worker 1]. Starting task 713.
[Worker 1]. Starting task 717.
[Worker 1]. Starting task 721.
[Worker 1]. Starting task 725.
[Worker 1]. Starting task 729.
[Worker 1]. Starting task 733.
[Worker 1]. Starting task 737.
[Worker 1]. Starting task 741.
[Worker 1]. Starting task 745.
[Worker 1]. Starting task 749.
[Worker 1]. Starting task 753.
[Worker 1]. Starting task 757.
[Worker 1]. Starting task 761.
[Worker 1]. Starting task 765.
[Worker 1]. Starting task 769.
[Worker 1]. Starting task 773.
[Worker 1]. Starting task 777.
[Worker 1]. Starting task 781.
[Worker 1]. Starting task 785.
[Worker 1]. Starting task 789.
[Worker 1]. Starting task 793.
[Worker 1]. Starting task 797.
[Worker 3]. Starting task 3.
[Worker 3]. Starting task 7.
[Worker 3]. Starting task 11.
[Worker 3]. Starting task 15.
[Worker 3]. Starting task 19.
[Worker 3]. Starting task 23.
[Worker 3]. Starting task 27.
[Worker 3]. Starting task 31.
[Worker 3]. Starting task 35.
[Worker 3]. Starting task 39.
[Worker 3]. Starting task 43.
[Worker 3]. Starting task 47.
[Worker 3]. Starting task 51.
[Worker 3]. Starting task 55.
[Worker 3]. Starting task 59.
[Worker 3]. Starting task 63.
[Worker 3]. Starting task 67.
[Worker 3]. Starting task 71.
[Worker 3]. Starting task 75.
[Worker 3]. Starting task 79.
[Worker 3]. Starting task 83.
[Worker 3]. Starting task 87.
[Worker 3]. Starting task 91.
[Worker 3]. Starting task 95.
[Worker 3]. Starting task 99.
[Worker 3]. Starting task 103.
[Worker 3]. Starting task 107.
[Worker 3]. Starting task 111.
[Worker 3]. Starting task 115.
[Worker 3]. Starting task 119.
[Worker 3]. Starting task 123.
[Worker 3]. Starting task 127.
[Worker 3]. Starting task 131.
[Worker 3]. Starting task 135.
[Worker 3]. Starting task 139.
[Worker 3]. Starting task 143.
[Worker 3]. Starting task 147.
[Worker 3]. Starting task 151.
[Worker 3]. Starting task 155.
[Worker 3]. Starting task 159.
[Worker 3]. Starting task 163.
[Worker 3]. Starting task 167.
[Worker 3]. Starting task 171.
[Worker 3]. Starting task 175.
[Worker 3]. Starting task 179.
[Worker 3]. Starting task 183.
[Worker 3]. Starting task 187.
[Worker 3]. Starting task 191.
[Worker 3]. Starting task 195.
[Worker 3]. Starting task 199.
[Worker 3]. Starting task 203.
[Worker 3]. Starting task 207.
[Worker 3]. Starting task 211.
[Worker 3]. Starting task 215.
[Worker 3]. Starting task 219.
[Worker 3]. Starting task 223.
[Worker 3]. Starting task 227.
[Worker 3]. Starting task 231.
[Worker 3]. Starting task 235.
[Worker 3]. Starting task 239.
[Worker 3]. Starting task 243.
[Worker 3]. Starting task 247.
[Worker 3]. Starting task 251.
[Worker 3]. Starting task 255.
[Worker 3]. Starting task 259.
[Worker 3]. Starting task 263.
[Worker 3]. Starting task 267.
[Worker 3]. Starting task 271.
[Worker 3]. Starting task 275.
[Worker 3]. Starting task 279.
[Worker 3]. Starting task 283.
[Worker 3]. Starting task 287.
[Worker 3]. Starting task 291.
[Worker 3]. Starting task 295.
[Worker 3]. Starting task 299.
[Worker 3]. Starting task 303.
[Worker 3]. Starting task 307.
[Worker 3]. Starting task 311.
[Worker 3]. Starting task 315.
[Worker 3]. Starting task 319.
[Worker 3]. Starting task 323.
[Worker 3]. Starting task 327.
[Worker 3]. Starting task 331.
[Worker 3]. Starting task 335.
[Worker 3]. Starting task 339.
[Worker 3]. Starting task 343.
[Worker 3]. Starting task 347.
[Worker 3]. Starting task 351.
[Worker 3]. Starting task 355.
[Worker 3]. Starting task 359.
[Worker 3]. Starting task 363.
[Worker 3]. Starting task 367.
[Worker 3]. Starting task 371.
[Worker 3]. Starting task 375.
[Worker 3]. Starting task 379.
[Worker 3]. Starting task 383.
[Worker 3]. Starting task 387.
[Worker 3]. Starting task 391.
[Worker 3]. Starting task 395.
[Worker 3]. Starting task 399.
[Worker 3]. Starting task 403.
[Worker 3]. Starting task 407.
[Worker 3]. Starting task 411.
[Worker 3]. Starting task 415.
[Worker 3]. Starting task 419.
[Worker 3]. Starting task 423.
[Worker 3]. Starting task 427.
[Worker 3]. Starting task 431.
[Worker 3]. Starting task 435.
[Worker 3]. Starting task 439.
[Worker 3]. Starting task 443.
[Worker 3]. Starting task 447.
[Worker 3]. Starting task 451.
[Worker 3]. Starting task 455.
[Worker 3]. Starting task 459.
[Worker 3]. Starting task 463.
[Worker 3]. Starting task 467.
[Worker 3]. Starting task 471.
[Worker 3]. Starting task 475.
[Worker 3]. Starting task 479.
[Worker 3]. Starting task 483.
[Worker 3]. Starting task 487.
[Worker 3]. Starting task 491.
[Worker 3]. Starting task 495.
[Worker 3]. Starting task 499.
[Worker 3]. Starting task 503.
[Worker 3]. Starting task 507.
[Worker 3]. Starting task 511.
[Worker 3]. Starting task 515.
[Worker 3]. Starting task 519.
[Worker 3]. Starting task 523.
[Worker 3]. Starting task 527.
[Worker 3]. Starting task 531.
[Worker 3]. Starting task 535.
[Worker 3]. Starting task 539.
[Worker 3]. Starting task 543.
[Worker 3]. Starting task 547.
[Worker 3]. Starting task 551.
[Worker 3]. Starting task 555.
[Worker 3]. Starting task 559.
[Worker 3]. Starting task 563.
[Worker 3]. Starting task 567.
[Worker 3]. Starting task 571.
[Worker 3]. Starting task 575.
[Worker 3]. Starting task 579.
[Worker 3]. Starting task 583.
[Worker 3]. Starting task 587.
[Worker 3]. Starting task 591.
[Worker 3]. Starting task 595.
[Worker 3]. Starting task 599.
[Worker 3]. Starting task 603.
[Worker 3]. Starting task 607.
[Worker 3]. Starting task 611.
[Worker 3]. Starting task 615.
[Worker 3]. Starting task 619.
[Worker 3]. Starting task 623.
[Worker 3]. Starting task 627.
[Worker 3]. Starting task 631.
[Worker 3]. Starting task 635.
[Worker 3]. Starting task 639.
[Worker 3]. Starting task 643.
[Worker 3]. Starting task 647.
[Worker 3]. Starting task 651.
[Worker 3]. Starting task 655.
[Worker 3]. Starting task 659.
[Worker 3]. Starting task 663.
[Worker 3]. Starting task 667.
[Worker 3]. Starting task 671.
[Worker 3]. Starting task 675.
[Worker 3]. Starting task 679.
[Worker 3]. Starting task 683.
[Worker 3]. Starting task 687.
[Worker 3]. Starting task 691.
[Worker 3]. Starting task 695.
[Worker 3]. Starting task 699.
[Worker 3]. Starting task 703.
[Worker 3]. Starting task 707.
[Worker 3]. Starting task 711.
[Worker 3]. Starting task 715.
[Worker 3]. Starting task 719.
[Worker 3]. Starting task 723.
[Worker 3]. Starting task 727.
[Worker 3]. Starting task 731.
[Worker 3]. Starting task 735.
[Worker 3]. Starting task 739.
[Worker 3]. Starting task 743.
[Worker 3]. Starting task 747.
[Worker 3]. Starting task 751.
[Worker 3]. Starting task 755.
[Worker 3]. Starting task 759.
[Worker 3]. Starting task 763.
[Worker 3]. Starting task 767.
[Worker 3]. Starting task 771.
[Worker 3]. Starting task 775.
[Worker 3]. Starting task 779.
[Worker 3]. Starting task 783.
[Worker 3]. Starting task 787.
[Worker 3]. Starting task 791.
[Worker 3]. Starting task 795.
[Worker 3]. Starting task 799.
combining...
Combining factorizations for k=3.
Combining factorizations for k=4.
Combining factorizations for k=5.
Combining factorizations for k=6.
Combining factorizations for k=7.
Combining factorizations for k=8.
Combining factorizations for k=9.
Combining factorizations for k=10.
done...
xeno_cnmf_run is up to date
